<?xml version="1.0"?>
<robot name="two_boxes_robot">

  <!-- Dummy Root Link -->
  <link name="root"/>

  <!-- Fixed Joint to Connect Dummy Root Link to Box1 -->
  <joint name="fixed_root_to_box1" type="fixed">
    <parent link="root"/>
    <child link="box1"/>
    <origin xyz="0 0 0" rpy="0 0 0"/>
  </joint>

  <!-- Link 1: Base box -->
  <link name="box1">
    <visual>
      <geometry>
        <box size="1 1 1"/>
      </geometry>
      <material name="red">
        <color rgba="1 0 0 1"/>
      </material>
    </visual>
    <collision>
      <geometry>
        <box size="1 1 1"/>
      </geometry>
    </collision>
    <inertial>
      <mass value="1.0"/>
      <inertia ixx="0.1" ixy="0.0" ixz="0.0" iyy="0.1" iyz="0.0" izz="0.1"/>
    </inertial>
  </link>

  <!-- Link 2: Moving box -->
  <link name="box2">
    <visual>
      <geometry>
        <box size="0.5 0.5 0.5"/>
      </geometry>
      <material name="blue">
        <color rgba="0 0 1 1"/>
      </material>
    </visual>
    <collision>
      <geometry>
        <box size="0.5 0.5 0.5"/>
      </geometry>
    </collision>
    <inertial>
      <mass value="0.5"/>
      <inertia ixx="0.05" ixy="0.0" ixz="0.0" iyy="0.05" iyz="0.0" izz="0.05"/>
    </inertial>
  </link>

  <!-- Joint: Revolute -->
  <joint name="revolute_joint" type="revolute">
    <parent link="box1"/>
    <child link="box2"/>
    <origin xyz="0 0 0.5" rpy="0 0 0"/>
    <axis xyz="0 0 1"/>
    <limit lower="-1.57" upper="1.57" effort="10.0" velocity="1.0"/>
  </joint>

</robot>

